{"name": "test_func2", "status": "failed", "statusDetails": {"message": "AssertionError: assert 4 == 5\n +  where 4 = func(3)", "trace": "..\\TestCase\\test_001.py:19: in test_func2\n    assert func(3) == 5  # 失败示例\nE   assert 4 == 5\nE    +  where 4 = func(3)"}, "start": 1631957862804, "stop": 1631957862804, "uuid": "20b78ebd-81b2-4c4f-bb05-8c2eafe9ee3c", "historyId": "d1f7fdc44fac24f2e1e1180661e86b36", "testCaseId": "c110c5c33c6081c3cf87f10dd4bf4bab", "fullName": "TestCase.test_001#test_func2", "labels": [{"name": "parentSuite", "value": "TestCase"}, {"name": "suite", "value": "test_001"}, {"name": "host", "value": "WIN-28O6201FKQP"}, {"name": "thread", "value": "14176-MainThread"}, {"name": "framework", "value": "pytest"}, {"name": "language", "value": "cpython3"}, {"name": "package", "value": "TestCase.test_001"}]}